2020-01-04 15:27:02,908 ERROR: Exception on /services [GET] [in c:\users\hp\appdata\local\programs\python\python38-32\lib\site-packages\flask\app.py:1890]
Traceback (most recent call last):
  File "c:\users\hp\appdata\local\programs\python\python38-32\lib\site-packages\flask\app.py", line 2446, in wsgi_app
    response = self.full_dispatch_request()
  File "c:\users\hp\appdata\local\programs\python\python38-32\lib\site-packages\flask\app.py", line 1951, in full_dispatch_request
    rv = self.handle_user_exception(e)
  File "c:\users\hp\appdata\local\programs\python\python38-32\lib\site-packages\flask\app.py", line 1820, in handle_user_exception
    reraise(exc_type, exc_value, tb)
  File "c:\users\hp\appdata\local\programs\python\python38-32\lib\site-packages\flask\_compat.py", line 39, in reraise
    raise value
  File "c:\users\hp\appdata\local\programs\python\python38-32\lib\site-packages\flask\app.py", line 1949, in full_dispatch_request
    rv = self.dispatch_request()
  File "c:\users\hp\appdata\local\programs\python\python38-32\lib\site-packages\flask\app.py", line 1935, in dispatch_request
    return self.view_functions[rule.endpoint](**req.view_args)
  File "C:\Users\HP\Desktop\talentdisha\app\main\routes.py", line 54, in services
    return render_template('services.html', title='Services')
  File "c:\users\hp\appdata\local\programs\python\python38-32\lib\site-packages\flask\templating.py", line 137, in render_template
    return _render(
  File "c:\users\hp\appdata\local\programs\python\python38-32\lib\site-packages\flask\templating.py", line 120, in _render
    rv = template.render(context)
  File "c:\users\hp\appdata\local\programs\python\python38-32\lib\site-packages\jinja2\asyncsupport.py", line 76, in render
    return original_render(self, *args, **kwargs)
  File "c:\users\hp\appdata\local\programs\python\python38-32\lib\site-packages\jinja2\environment.py", line 1008, in render
    return self.environment.handle_exception(exc_info, True)
  File "c:\users\hp\appdata\local\programs\python\python38-32\lib\site-packages\jinja2\environment.py", line 780, in handle_exception
    reraise(exc_type, exc_value, tb)
  File "c:\users\hp\appdata\local\programs\python\python38-32\lib\site-packages\jinja2\_compat.py", line 37, in reraise
    raise value.with_traceback(tb)
  File "C:\Users\HP\Desktop\talentdisha\app\templates\services.html", line 186, in <module>
    <li><a href="{{ url_for('who_we_are') }}"><span class="glyphicon glyphicon-user"></span> Who We Are</a></li>
  File "c:\users\hp\appdata\local\programs\python\python38-32\lib\site-packages\flask\helpers.py", line 370, in url_for
    return appctx.app.handle_url_build_error(error, endpoint, values)
  File "c:\users\hp\appdata\local\programs\python\python38-32\lib\site-packages\flask\app.py", line 2215, in handle_url_build_error
    reraise(exc_type, exc_value, tb)
  File "c:\users\hp\appdata\local\programs\python\python38-32\lib\site-packages\flask\_compat.py", line 39, in reraise
    raise value
  File "c:\users\hp\appdata\local\programs\python\python38-32\lib\site-packages\flask\helpers.py", line 357, in url_for
    rv = url_adapter.build(
  File "c:\users\hp\appdata\local\programs\python\python38-32\lib\site-packages\werkzeug\routing.py", line 2020, in build
    raise BuildError(endpoint, values, method, self)
werkzeug.routing.BuildError: Could not build url for endpoint 'who_we_are'. Did you mean 'main.who_we_are' instead?
2020-01-04 15:29:33,670 INFO: Microblog startup [in C:\Users\HP\Desktop\talentdisha\app\__init__.py:80]
2020-01-04 15:30:51,892 INFO: Microblog startup [in C:\Users\HP\Desktop\talentdisha\app\__init__.py:80]
2020-01-04 15:33:41,370 INFO: Microblog startup [in C:\Users\HP\Desktop\talentdisha\app\__init__.py:80]
2020-01-04 15:34:54,223 INFO: Microblog startup [in C:\Users\HP\Desktop\talentdisha\app\__init__.py:80]
2020-01-04 15:37:37,961 INFO: Microblog startup [in C:\Users\HP\Desktop\talentdisha\app\__init__.py:80]
2020-01-04 15:39:55,718 INFO: Microblog startup [in C:\Users\HP\Desktop\talentdisha\app\__init__.py:80]
