2019-12-17 22:51:57,352INFO: Microblog startup [in C:\Users\HP\Desktop\hp1\app\__init__.py:45]
2019-12-17 22:52:11,298ERROR: Exception on /edit_profile [POST] [in c:\users\hp\desktop\hp1\venv\lib\site-packages\flask\app.py:1890]
Traceback (most recent call last):
  File "c:\users\hp\desktop\hp1\venv\lib\site-packages\sqlalchemy\engine\base.py", line 1245, in _execute_context
    self.dialect.do_execute(
  File "c:\users\hp\desktop\hp1\venv\lib\site-packages\sqlalchemy\engine\default.py", line 581, in do_execute
    cursor.execute(statement, parameters)
sqlite3.IntegrityError: UNIQUE constraint failed: user.username

The above exception was the direct cause of the following exception:

Traceback (most recent call last):
  File "c:\users\hp\desktop\hp1\venv\lib\site-packages\flask\app.py", line 2446, in wsgi_app
    response = self.full_dispatch_request()
  File "c:\users\hp\desktop\hp1\venv\lib\site-packages\flask\app.py", line 1951, in full_dispatch_request
    rv = self.handle_user_exception(e)
  File "c:\users\hp\desktop\hp1\venv\lib\site-packages\flask\app.py", line 1820, in handle_user_exception
    reraise(exc_type, exc_value, tb)
  File "c:\users\hp\desktop\hp1\venv\lib\site-packages\flask\_compat.py", line 39, in reraise
    raise value
  File "c:\users\hp\desktop\hp1\venv\lib\site-packages\flask\app.py", line 1949, in full_dispatch_request
    rv = self.dispatch_request()
  File "c:\users\hp\desktop\hp1\venv\lib\site-packages\flask\app.py", line 1935, in dispatch_request
    return self.view_functions[rule.endpoint](**req.view_args)
  File "c:\users\hp\desktop\hp1\venv\lib\site-packages\flask_login\utils.py", line 261, in decorated_view
    return func(*args, **kwargs)
  File "C:\Users\HP\Desktop\hp1\app\routes.py", line 226, in edit_profile
    db.session.commit()
  File "c:\users\hp\desktop\hp1\venv\lib\site-packages\sqlalchemy\orm\scoping.py", line 162, in do
    return getattr(self.registry(), name)(*args, **kwargs)
  File "c:\users\hp\desktop\hp1\venv\lib\site-packages\sqlalchemy\orm\session.py", line 1027, in commit
    self.transaction.commit()
  File "c:\users\hp\desktop\hp1\venv\lib\site-packages\sqlalchemy\orm\session.py", line 494, in commit
    self._prepare_impl()
  File "c:\users\hp\desktop\hp1\venv\lib\site-packages\sqlalchemy\orm\session.py", line 473, in _prepare_impl
    self.session.flush()
  File "c:\users\hp\desktop\hp1\venv\lib\site-packages\sqlalchemy\orm\session.py", line 2470, in flush
    self._flush(objects)
  File "c:\users\hp\desktop\hp1\venv\lib\site-packages\sqlalchemy\orm\session.py", line 2608, in _flush
    transaction.rollback(_capture_exception=True)
  File "c:\users\hp\desktop\hp1\venv\lib\site-packages\sqlalchemy\util\langhelpers.py", line 68, in __exit__
    compat.reraise(exc_type, exc_value, exc_tb)
  File "c:\users\hp\desktop\hp1\venv\lib\site-packages\sqlalchemy\util\compat.py", line 153, in reraise
    raise value
  File "c:\users\hp\desktop\hp1\venv\lib\site-packages\sqlalchemy\orm\session.py", line 2568, in _flush
    flush_context.execute()
  File "c:\users\hp\desktop\hp1\venv\lib\site-packages\sqlalchemy\orm\unitofwork.py", line 422, in execute
    rec.execute(self)
  File "c:\users\hp\desktop\hp1\venv\lib\site-packages\sqlalchemy\orm\unitofwork.py", line 586, in execute
    persistence.save_obj(
  File "c:\users\hp\desktop\hp1\venv\lib\site-packages\sqlalchemy\orm\persistence.py", line 230, in save_obj
    _emit_update_statements(
  File "c:\users\hp\desktop\hp1\venv\lib\site-packages\sqlalchemy\orm\persistence.py", line 995, in _emit_update_statements
    c = cached_connections[connection].execute(
  File "c:\users\hp\desktop\hp1\venv\lib\site-packages\sqlalchemy\engine\base.py", line 982, in execute
    return meth(self, multiparams, params)
  File "c:\users\hp\desktop\hp1\venv\lib\site-packages\sqlalchemy\sql\elements.py", line 287, in _execute_on_connection
    return connection._execute_clauseelement(self, multiparams, params)
  File "c:\users\hp\desktop\hp1\venv\lib\site-packages\sqlalchemy\engine\base.py", line 1095, in _execute_clauseelement
    ret = self._execute_context(
  File "c:\users\hp\desktop\hp1\venv\lib\site-packages\sqlalchemy\engine\base.py", line 1249, in _execute_context
    self._handle_dbapi_exception(
  File "c:\users\hp\desktop\hp1\venv\lib\site-packages\sqlalchemy\engine\base.py", line 1476, in _handle_dbapi_exception
    util.raise_from_cause(sqlalchemy_exception, exc_info)
  File "c:\users\hp\desktop\hp1\venv\lib\site-packages\sqlalchemy\util\compat.py", line 398, in raise_from_cause
    reraise(type(exception), exception, tb=exc_tb, cause=cause)
  File "c:\users\hp\desktop\hp1\venv\lib\site-packages\sqlalchemy\util\compat.py", line 152, in reraise
    raise value.with_traceback(tb)
  File "c:\users\hp\desktop\hp1\venv\lib\site-packages\sqlalchemy\engine\base.py", line 1245, in _execute_context
    self.dialect.do_execute(
  File "c:\users\hp\desktop\hp1\venv\lib\site-packages\sqlalchemy\engine\default.py", line 581, in do_execute
    cursor.execute(statement, parameters)
sqlalchemy.exc.IntegrityError: (sqlite3.IntegrityError) UNIQUE constraint failed: user.username
[SQL: UPDATE user SET username=?, about_me=? WHERE user.id = ?]
[parameters: ('john', '', 1)]
(Background on this error at: http://sqlalche.me/e/gkpj)
2019-12-17 23:00:40,831INFO: Microblog startup [in C:\Users\HP\Desktop\hp1\app\__init__.py:45]
2019-12-19 02:35:12,885INFO: Microblog startup [in C:\Users\HP\Desktop\hp1\app\__init__.py:45]
2019-12-19 02:36:04,012INFO: Microblog startup [in C:\Users\HP\Desktop\hp1\app\__init__.py:45]
2019-12-19 02:36:58,522INFO: Microblog startup [in C:\Users\HP\Desktop\hp1\app\__init__.py:45]
2019-12-19 02:37:21,664INFO: Microblog startup [in C:\Users\HP\Desktop\hp1\app\__init__.py:45]
2019-12-19 02:42:15,021INFO: Microblog startup [in C:\Users\HP\Desktop\hp1\app\__init__.py:45]
2019-12-19 02:43:17,489INFO: Microblog startup [in C:\Users\HP\Desktop\hp1\app\__init__.py:45]
2019-12-21 14:20:34,759INFO: Microblog startup [in C:\Users\HP\Desktop\hp1\app\__init__.py:47]
2019-12-21 14:20:51,339ERROR: Exception on /reset_password_request [POST] [in c:\users\hp\desktop\hp1\venv\lib\site-packages\flask\app.py:1890]
Traceback (most recent call last):
  File "c:\users\hp\desktop\hp1\venv\lib\site-packages\flask\app.py", line 2446, in wsgi_app
    response = self.full_dispatch_request()
  File "c:\users\hp\desktop\hp1\venv\lib\site-packages\flask\app.py", line 1951, in full_dispatch_request
    rv = self.handle_user_exception(e)
  File "c:\users\hp\desktop\hp1\venv\lib\site-packages\flask\app.py", line 1820, in handle_user_exception
    reraise(exc_type, exc_value, tb)
  File "c:\users\hp\desktop\hp1\venv\lib\site-packages\flask\_compat.py", line 39, in reraise
    raise value
  File "c:\users\hp\desktop\hp1\venv\lib\site-packages\flask\app.py", line 1949, in full_dispatch_request
    rv = self.dispatch_request()
  File "c:\users\hp\desktop\hp1\venv\lib\site-packages\flask\app.py", line 1935, in dispatch_request
    return self.view_functions[rule.endpoint](**req.view_args)
  File "C:\Users\HP\Desktop\hp1\app\routes.py", line 141, in reset_password_request
    send_password_reset_email(user)
  File "C:\Users\HP\Desktop\hp1\app\email.py", line 18, in send_password_reset_email
    text_body=render_template('email/reset_password.txt',
  File "c:\users\hp\desktop\hp1\venv\lib\site-packages\flask\templating.py", line 137, in render_template
    return _render(
  File "c:\users\hp\desktop\hp1\venv\lib\site-packages\flask\templating.py", line 120, in _render
    rv = template.render(context)
  File "c:\users\hp\desktop\hp1\venv\lib\site-packages\jinja2\asyncsupport.py", line 76, in render
    return original_render(self, *args, **kwargs)
  File "c:\users\hp\desktop\hp1\venv\lib\site-packages\jinja2\environment.py", line 1008, in render
    return self.environment.handle_exception(exc_info, True)
  File "c:\users\hp\desktop\hp1\venv\lib\site-packages\jinja2\environment.py", line 780, in handle_exception
    reraise(exc_type, exc_value, tb)
  File "c:\users\hp\desktop\hp1\venv\lib\site-packages\jinja2\_compat.py", line 37, in reraise
    raise value.with_traceback(tb)
  File "C:\Users\HP\Desktop\hp1\app\templates\email\reset_password.txt", line 1, in <module>
    Dear {{ user.username }},
  File "c:\users\hp\desktop\hp1\venv\lib\site-packages\jinja2\environment.py", line 430, in getattr
    return getattr(obj, attribute)
jinja2.exceptions.UndefinedError: 'user' is undefined
2019-12-21 14:21:45,201INFO: Microblog startup [in C:\Users\HP\Desktop\hp1\app\__init__.py:47]
